<?xml version="1.0" encoding="utf-8"?>
<!-- =================================================================================== -->
<!-- |    This document was autogenerated by xacro from strirus_gamma.xacro            | -->
<!-- |    EDITING THIS FILE BY HAND IS NOT RECOMMENDED                                 | -->
<!-- =================================================================================== -->
<robot name="Strirus_gamma" xmlns:xacro="http://www.ros.org/wiki/xacro">
  <gazebo>
    <self_collide> 1 </self_collide>
  </gazebo>
  <!-- 	<xacro:arg name="namespace" default="/"/>
	<xacro:property name="namespace" value="$(arg namespace)" /> -->
  <!-- Constants for simulating -->
  <!-- Xacro arg provides xacro.py file.xacro real_number_of_legs:=12 -->
  <!-- Import Rviz colors -->
  <material name="black">
    <color rgba="0.0 0.0 0.0 1.0"/>
  </material>
  <material name="blue">
    <color rgba="0.0 0.0 0.8 1.0"/>
  </material>
  <material name="green">
    <color rgba="0.0 0.8 0.0 1.0"/>
  </material>
  <material name="grey">
    <color rgba="0.2 0.2 0.2 1.0"/>
  </material>
  <material name="orange">
    <color rgba="1.0 0.423529411765 0.0392156862745 1.0"/>
  </material>
  <material name="brown">
    <color rgba="0.870588235294 0.811764705882 0.764705882353 1.0"/>
  </material>
  <material name="red">
    <color rgba="0.8 0.0 0.0 1.0"/>
  </material>
  <material name="white">
    <color rgba="1.0 1.0 1.0 1.0"/>
  </material>
  <!-- Body description -->
  <link name="base_link"/>
  <joint name="base_link_body_1_part_fixed" type="fixed">
    <parent link="base_link"/>
    <child link="body_1_part"/>
  </joint>
  <!-- /////////////// -->
  <!-- omni_deg in DEG!! not  in rad -->
  <!--body 1 part -->
  <link name="body_1_part">
    <inertial>
      <mass value="2.388930632"/>
      <origin rpy="0  0  0" xyz="0.093004592 -0.000003767 0.022606835"/>
      <inertia ixx="0.029836761" ixy="-0.000001989" ixz="0.005143199" iyy="0.038129150" iyz="0.000000032" izz="0.064532466"/>
    </inertial>
    <collision>
      <origin rpy="0  0  0" xyz="0 0 0"/>
      <geometry>
        <mesh filename="package://strirus_cad_design/stl/body_1_30_part.stl" scale="1 1 1"/>
      </geometry>
    </collision>
    <visual>
      <origin rpy="0  0  0" xyz="0 0 0"/>
      <geometry>
        <mesh filename="package://strirus_cad_design/stl/body_1_30_part.stl" scale="1 1 1"/>
      </geometry>
      <material name="green"/>
    </visual>
  </link>
  <!--body 2 part -->
  <link name="body_2_part">
    <inertial>
      <mass value="2.355831379"/>
      <origin rpy="0  0  0" xyz="0.461055522 0.000005875 0.022371110"/>
      <inertia ixx="0.029769456" ixy="0.000004675" ixz="0.024189823" iyy="0.518172151" iyz="0.000000208" izz="0.544629121"/>
    </inertial>
    <collision>
      <origin rpy="0  0  0" xyz="0 0 0"/>
      <geometry>
        <mesh filename="package://strirus_cad_design/stl/body_2_30_part.stl" scale="1 1 1"/>
      </geometry>
    </collision>
    <visual>
      <origin rpy="0  0  0" xyz="0 0 0"/>
      <geometry>
        <mesh filename="package://strirus_cad_design/stl/body_2_30_part.stl" scale="1 1 1"/>
      </geometry>
      <material name="orange"/>
    </visual>
  </link>
  <!-- bridge part -->
  <!-- brdige 1 part -->
  <link name="bridge_1_part">
    <inertial>
      <mass value="0.093452612"/>
      <origin rpy="0  0  0" xyz="0.253688724 0.000000000 0.025077504"/>
      <inertia ixx="0.000293438" ixy="0.000000000" ixz="0.000594486" iyy="0.006102775" iyz="0.000000000" izz="0.006245808"/>
    </inertial>
    <collision>
      <origin rpy="0  0  0" xyz="0 0 0"/>
      <geometry>
        <mesh filename="package://strirus_cad_design/stl/bridge_1_part.stl" scale="1 1 1"/>
      </geometry>
    </collision>
    <visual>
      <origin rpy="0  0  0" xyz="0 0 0"/>
      <geometry>
        <mesh filename="package://strirus_cad_design/stl/bridge_1_part.stl" scale="1 1 1"/>
      </geometry>
      <material name="white"/>
    </visual>
  </link>
  <!-- brdige 2 part -->
  <link name="bridge_2_part">
    <inertial>
      <mass value="0.093452612"/>
      <origin rpy="0  0  0" xyz="0.300311235 0.000000000 0.025089023"/>
      <inertia ixx="0.000273936" ixy="0.000000000" ixz="0.000704167" iyy="0.008516604" iyz="0.000000000" izz="0.008640028"/>
    </inertial>
    <collision>
      <origin rpy="0  0  0" xyz="0 0 0"/>
      <geometry>
        <mesh filename="package://strirus_cad_design/stl/bridge_2_part.stl" scale="1 1 1"/>
      </geometry>
    </collision>
    <visual>
      <origin rpy="0  0  0" xyz="0 0 0"/>
      <geometry>
        <mesh filename="package://strirus_cad_design/stl/bridge_2_part.stl" scale="1 1 1"/>
      </geometry>
      <material name="grey"/>
    </visual>
  </link>
  <!-- Joints -->
  <joint name="bridge_2_part_body_2_part_fixed" type="fixed">
    <parent link="bridge_2_part"/>
    <child link="body_2_part"/>
  </joint>
  <joint name="body_1_part_bridge_1_part_fixed" type="fixed">
    <parent link="body_1_part"/>
    <child link="bridge_1_part"/>
  </joint>
  <joint name="bridge_1_part_bridge_2_part_revolute" type="revolute">
    <parent link="bridge_1_part"/>
    <child link="bridge_2_part"/>
    <origin rpy="0       0      0" xyz="0.277 0 0.025"/>
    <axis xyz="0 1  0"/>
    <limit effort="30" lower="-1.308996939" upper="1.308996939" velocity="5"/>
    <joint_properties damping="0.0" friction="0.0"/>
  </joint>
</robot>

