<?xml version="1.0" encoding="utf-8"?>
<!-- =================================================================================== -->
<!-- |    This document was autogenerated by xacro from strirus_gamma.xacro            | -->
<!-- |    EDITING THIS FILE BY HAND IS NOT RECOMMENDED                                 | -->
<!-- =================================================================================== -->
<robot name="strirus_gamma" xmlns:xacro="http://www.ros.org/wiki/xacro">
  <gazebo>
    <self_collide>1</self_collide>
  </gazebo>
  <!-- 	<xacro:arg name="namespace" default="/"/>
        <xacro:property name="namespace" value="$(arg namespace)" /> -->
  <!-- Constants for simulating -->
  <!-- Xacro arg provides xacro.py file.xacro real_number_of_legs:=12 -->
  <!-- Import Rviz colors -->
  <material name="black">
    <color rgba="0.0 0.0 0.0 1.0"/>
  </material>
  <material name="blue">
    <color rgba="0.0 0.0 0.8 1.0"/>
  </material>
  <material name="green">
    <color rgba="0.0 0.8 0.0 1.0"/>
  </material>
  <material name="grey">
    <color rgba="0.2 0.2 0.2 1.0"/>
  </material>
  <material name="orange">
    <color rgba="1.0 0.423529411765 0.0392156862745 1.0"/>
  </material>
  <material name="brown">
    <color rgba="0.870588235294 0.811764705882 0.764705882353 1.0"/>
  </material>
  <material name="red">
    <color rgba="0.8 0.0 0.0 1.0"/>
  </material>
  <material name="white">
    <color rgba="1.0 1.0 1.0 1.0"/>
  </material>
  <!-- Body description -->
  <link name="base_footprint"/>
  <joint name="base_footprint_body_1_part_fixed" type="fixed">
    <parent link="base_footprint"/>
    <child link="body_1_part"/>
    <origin rpy="0  0  0" xyz="0 0 0.055"/>
  </joint>
  <!-- /////////////// -->
  <!-- omni_deg in DEG!! not  in rad -->
  <!--body 1 part -->
  <link name="body_1_part">
    <inertial>
      <mass value="2.388930632"/>
      <origin rpy="0  0  0" xyz="0.096209300 -0.000003507 -0.002393165"/>
      <inertia ixx="0.017027739" ixy="-0.000001088" ixz="0.000137008" iyy="0.016226695" iyz="0.000000214" izz="0.032262805"/>
    </inertial>
    <collision>
      <origin rpy="0  0  0" xyz="0 0 0"/>
      <geometry>
        <mesh filename="package://strirus_cad_design/stl/collision/body_1_0_part.stl" scale="1 1 1"/>
      </geometry>
    </collision>
    <visual>
      <origin rpy="0  0  0" xyz="0 0 0"/>
      <geometry>
        <mesh filename="package://strirus_cad_design/stl/visual/body_1_0_part.stl" scale="1 1 1"/>
      </geometry>
      <material name="white"/>
    </visual>
  </link>
  <!--body 2 part -->
  <link name="body_2_part">
    <inertial>
      <mass value="2.355831379"/>
      <origin rpy="0  0  0" xyz="0.150804467 0.000005611 -0.002719841"/>
      <inertia ixx="0.018410893" ixy="-0.000001632" ixz="-0.000135654" iyy="0.016191801" iyz="-0.000000080" izz="0.033648014"/>
    </inertial>
    <collision>
      <origin rpy="0  0  0" xyz="0 0 0"/>
      <geometry>
        <mesh filename="package://strirus_cad_design/stl/collision/body_2_0_part.stl" scale="1 1 1"/>
      </geometry>
    </collision>
    <visual>
      <origin rpy="0  0  0" xyz="0 0 0"/>
      <geometry>
        <mesh filename="package://strirus_cad_design/stl/visual/body_2_0_part.stl" scale="1 1 1"/>
      </geometry>
      <material name="orange"/>
    </visual>
  </link>
  <!-- bridge part -->
  <!-- brdige 1 part -->
  <link name="bridge_1_part">
    <inertial>
      <mass value="0.093452612"/>
      <origin rpy="0  0  0" xyz="0.006688724 0.000000000 0.000077504"/>
      <inertia ixx="0.000234667" ixy="0.000000000" ixz="0.000000048" iyy="0.000029584" iyz="0.000000000" izz="0.000231388"/>
    </inertial>
    <collision>
      <origin rpy="0  0  0" xyz="0 0 0"/>
      <geometry>
        <mesh filename="package://strirus_cad_design/stl/collision/bridge_1_part.stl" scale="1 1 1"/>
      </geometry>
    </collision>
    <visual>
      <origin rpy="0  0  0" xyz="0 0 0"/>
      <geometry>
        <mesh filename="package://strirus_cad_design/stl/visual/bridge_1_part.stl" scale="1 1 1"/>
      </geometry>
      <material name="white"/>
    </visual>
  </link>
  <!-- brdige 2 part -->
  <link name="bridge_2_part">
    <inertial>
      <mass value="0.093452612"/>
      <origin rpy="0  0  0" xyz="0.023311276 0.000000000 0.000077504"/>
      <inertia ixx="0.000215112" ixy="0.000000000" ixz="0.000000048" iyy="0.000029584" iyz="0.000000000" izz="0.000211832"/>
    </inertial>
    <collision>
      <origin rpy="0  0  0" xyz="-0 0 0"/>
      <geometry>
        <mesh filename="package://strirus_cad_design/stl/collision/bridge_2_part.stl" scale="1 1 1"/>
      </geometry>
    </collision>
    <visual>
      <origin rpy="0  0  0" xyz="-0 0 0"/>
      <geometry>
        <mesh filename="package://strirus_cad_design/stl/visual/bridge_2_part.stl" scale="1 1 1"/>
      </geometry>
      <material name="orange"/>
    </visual>
  </link>
  <joint name="bridge_1_part_bridge_2_part_revolute" type="revolute">
    <parent link="bridge_1_part"/>
    <child link="bridge_2_part"/>
    <origin rpy="0       0      0" xyz="0.03 0 0"/>
    <axis xyz="0 -1  0"/>
    <limit effort="30" lower="-1.308996939" upper="1.308996939" velocity="5"/>
    <joint_properties damping="0.0" friction="0.0"/>
  </joint>
  <joint name="body_1_part_bridge_1_part_revolute" type="revolute">
    <parent link="body_1_part"/>
    <child link="bridge_1_part"/>
    <origin rpy="0       0      0" xyz="0.247 0 0"/>
    <axis xyz="0 0  -1"/>
    <limit effort="30" lower="-0.261799387799" upper="0.261799387799" velocity="5"/>
    <joint_properties damping="0.0" friction="0.0"/>
  </joint>
  <joint name="bridge_2_part_body_2_part_fixed" type="fixed">
    <parent link="bridge_2_part"/>
    <child link="body_2_part"/>
    <origin rpy="0 0 0" xyz="0.03 0 0"/>
  </joint>
  <!-- 
            <xacro:property name="angle_for_0_l_leg" value="${angle_for_0_l_leg * deg2rad}"/>
            <xacro:property name="angle_btw_legs" value="${angle_btw_legs * deg2rad}"/> -->
  <!-- 		<xacro:property name="angle_coeff_left" value="${(angle_for_0_l_leg + angle_btw_legs * num) % 360 * deg2rad}" />
                <xacro:property name="angle_coeff_right" value="${-(angle_btw_legs * num) % 360 * deg2rad}" /> -->
  <link name="leg_left_5">
    <inertial>
      <mass value="0.010307884"/>
      <origin rpy="0 0 0" xyz="-0.008963344 0 -0.020168668"/>
      <inertia ixx="0.000004032" ixy="0" ixz="0.000000712" iyy="0.000004993" iyz="0" izz="0.000001071"/>
    </inertial>
    <collision>
      <origin rpy="0  0  0" xyz="0 0 0"/>
      <geometry>
        <mesh filename="package://strirus_cad_design/stl/collision/leg_55.stl" scale="1 1 1"/>
      </geometry>
    </collision>
    <visual>
      <origin rpy="0  0  0" xyz="0 0 0"/>
      <geometry>
        <mesh filename="package://strirus_cad_design/stl/visual/leg_55.stl" scale="1 1 1"/>
      </geometry>
      <material name="white"/>
    </visual>
  </link>
  <joint name="leg_left_5_revolute_joint" type="revolute">
    <child link="leg_left_5"/>
    <parent link="body_2_part"/>
    <origin rpy="0       0      0" xyz="-0.013 0.1515  0"/>
    <axis xyz="0 1  0"/>
    <limit effort="30" lower="-1e+100" upper="1e+100" velocity="3.0"/>
    <joint_properties damping="0.0" friction="0.0"/>
  </joint>
  <!-- 		<xacro:property name="angle_coeff_left" value="${(angle_for_0_l_leg + angle_btw_legs * num) % 360 * deg2rad}" />
                <xacro:property name="angle_coeff_right" value="${-(angle_btw_legs * num) % 360 * deg2rad}" /> -->
  <link name="leg_left_4">
    <inertial>
      <mass value="0.010307884"/>
      <origin rpy="0 0 0" xyz="-0.008963344 0 -0.020168668"/>
      <inertia ixx="0.000004032" ixy="0" ixz="0.000000712" iyy="0.000004993" iyz="0" izz="0.000001071"/>
    </inertial>
    <collision>
      <origin rpy="0  0  0" xyz="0 0 0"/>
      <geometry>
        <mesh filename="package://strirus_cad_design/stl/collision/leg_55.stl" scale="1 1 1"/>
      </geometry>
    </collision>
    <visual>
      <origin rpy="0  0  0" xyz="0 0 0"/>
      <geometry>
        <mesh filename="package://strirus_cad_design/stl/visual/leg_55.stl" scale="1 1 1"/>
      </geometry>
      <material name="white"/>
    </visual>
  </link>
  <joint name="leg_left_4_revolute_joint" type="revolute">
    <child link="leg_left_4"/>
    <parent link="body_2_part"/>
    <origin rpy="0       0      0" xyz="0.117 0.1345  0"/>
    <axis xyz="0 1  0"/>
    <limit effort="30" lower="-1e+100" upper="1e+100" velocity="3.0"/>
    <joint_properties damping="0.0" friction="0.0"/>
  </joint>
  <!-- 		<xacro:property name="angle_coeff_left" value="${(angle_for_0_l_leg + angle_btw_legs * num) % 360 * deg2rad}" />
                <xacro:property name="angle_coeff_right" value="${-(angle_btw_legs * num) % 360 * deg2rad}" /> -->
  <link name="leg_left_3">
    <inertial>
      <mass value="0.010307884"/>
      <origin rpy="0 0 0" xyz="-0.008963344 0 -0.020168668"/>
      <inertia ixx="0.000004032" ixy="0" ixz="0.000000712" iyy="0.000004993" iyz="0" izz="0.000001071"/>
    </inertial>
    <collision>
      <origin rpy="0  0  0" xyz="0 0 0"/>
      <geometry>
        <mesh filename="package://strirus_cad_design/stl/collision/leg_55.stl" scale="1 1 1"/>
      </geometry>
    </collision>
    <visual>
      <origin rpy="0  0  0" xyz="0 0 0"/>
      <geometry>
        <mesh filename="package://strirus_cad_design/stl/visual/leg_55.stl" scale="1 1 1"/>
      </geometry>
      <material name="white"/>
    </visual>
  </link>
  <joint name="leg_left_3_revolute_joint" type="revolute">
    <child link="leg_left_3"/>
    <parent link="body_2_part"/>
    <origin rpy="0       0      0" xyz="0.247 0.1515  0"/>
    <axis xyz="0 1  0"/>
    <limit effort="30" lower="-1e+100" upper="1e+100" velocity="3.0"/>
    <joint_properties damping="0.0" friction="0.0"/>
  </joint>
  <!-- 		<xacro:property name="angle_coeff_left" value="${(angle_for_0_l_leg + angle_btw_legs * num) % 360 * deg2rad}" />
                <xacro:property name="angle_coeff_right" value="${-(angle_btw_legs * num) % 360 * deg2rad}" /> -->
  <link name="leg_left_2">
    <inertial>
      <mass value="0.010307884"/>
      <origin rpy="0 0 0" xyz="-0.008963344 0 -0.020168668"/>
      <inertia ixx="0.000004032" ixy="0" ixz="0.000000712" iyy="0.000004993" iyz="0" izz="0.000001071"/>
    </inertial>
    <collision>
      <origin rpy="0  0  0" xyz="0 0 0"/>
      <geometry>
        <mesh filename="package://strirus_cad_design/stl/collision/leg_55.stl" scale="1 1 1"/>
      </geometry>
    </collision>
    <visual>
      <origin rpy="0  0  0" xyz="0 0 0"/>
      <geometry>
        <mesh filename="package://strirus_cad_design/stl/visual/leg_55.stl" scale="1 1 1"/>
      </geometry>
      <material name="white"/>
    </visual>
  </link>
  <joint name="leg_left_2_revolute_joint" type="revolute">
    <child link="leg_left_2"/>
    <parent link="body_1_part"/>
    <origin rpy="0       0      0" xyz="0.26 0.1345  0"/>
    <axis xyz="0 1  0"/>
    <limit effort="30" lower="-1e+100" upper="1e+100" velocity="3.0"/>
    <joint_properties damping="0.0" friction="0.0"/>
  </joint>
  <!-- 		<xacro:property name="angle_coeff_left" value="${(angle_for_0_l_leg + angle_btw_legs * num) % 360 * deg2rad}" />
                <xacro:property name="angle_coeff_right" value="${-(angle_btw_legs * num) % 360 * deg2rad}" /> -->
  <link name="leg_left_1">
    <inertial>
      <mass value="0.010307884"/>
      <origin rpy="0 0 0" xyz="-0.008963344 0 -0.020168668"/>
      <inertia ixx="0.000004032" ixy="0" ixz="0.000000712" iyy="0.000004993" iyz="0" izz="0.000001071"/>
    </inertial>
    <collision>
      <origin rpy="0  0  0" xyz="0 0 0"/>
      <geometry>
        <mesh filename="package://strirus_cad_design/stl/collision/leg_55.stl" scale="1 1 1"/>
      </geometry>
    </collision>
    <visual>
      <origin rpy="0  0  0" xyz="0 0 0"/>
      <geometry>
        <mesh filename="package://strirus_cad_design/stl/visual/leg_55.stl" scale="1 1 1"/>
      </geometry>
      <material name="white"/>
    </visual>
  </link>
  <joint name="leg_left_1_revolute_joint" type="revolute">
    <child link="leg_left_1"/>
    <parent link="body_1_part"/>
    <origin rpy="0       0      0" xyz="0.13 0.1515  0"/>
    <axis xyz="0 1  0"/>
    <limit effort="30" lower="-1e+100" upper="1e+100" velocity="3.0"/>
    <joint_properties damping="0.0" friction="0.0"/>
  </joint>
  <!-- 		<xacro:property name="angle_coeff_left" value="${(angle_for_0_l_leg + angle_btw_legs * num) % 360 * deg2rad}" />
                <xacro:property name="angle_coeff_right" value="${-(angle_btw_legs * num) % 360 * deg2rad}" /> -->
  <link name="leg_left_0">
    <inertial>
      <mass value="0.010307884"/>
      <origin rpy="0 0 0" xyz="-0.008963344 0 -0.020168668"/>
      <inertia ixx="0.000004032" ixy="0" ixz="0.000000712" iyy="0.000004993" iyz="0" izz="0.000001071"/>
    </inertial>
    <collision>
      <origin rpy="0  0  0" xyz="0 0 0"/>
      <geometry>
        <mesh filename="package://strirus_cad_design/stl/collision/leg_55.stl" scale="1 1 1"/>
      </geometry>
    </collision>
    <visual>
      <origin rpy="0  0  0" xyz="0 0 0"/>
      <geometry>
        <mesh filename="package://strirus_cad_design/stl/visual/leg_55.stl" scale="1 1 1"/>
      </geometry>
      <material name="white"/>
    </visual>
  </link>
  <joint name="leg_left_0_revolute_joint" type="revolute">
    <child link="leg_left_0"/>
    <parent link="body_1_part"/>
    <origin rpy="0       0      0" xyz="0.0 0.1345  0"/>
    <axis xyz="0 1  0"/>
    <limit effort="30" lower="-1e+100" upper="1e+100" velocity="3.0"/>
    <joint_properties damping="0.0" friction="0.0"/>
  </joint>
  <!-- 		<xacro:property name="angle_coeff_left" value="${(angle_for_0_l_leg + angle_btw_legs * num) % 360 * deg2rad}" />
                <xacro:property name="angle_coeff_right" value="${-(angle_btw_legs * num) % 360 * deg2rad}" /> -->
  <link name="leg_right_5">
    <inertial>
      <mass value="0.010307884"/>
      <origin rpy="0 0 0" xyz="-0.008963344 0 -0.020168668"/>
      <inertia ixx="0.000004032" ixy="0" ixz="0.000000712" iyy="0.000004993" iyz="0" izz="0.000001071"/>
    </inertial>
    <collision>
      <origin rpy="0  0  0" xyz="0 0 0"/>
      <geometry>
        <mesh filename="package://strirus_cad_design/stl/collision/leg_55.stl" scale="1 1 1"/>
      </geometry>
    </collision>
    <visual>
      <origin rpy="0  0  0" xyz="0 0 0"/>
      <geometry>
        <mesh filename="package://strirus_cad_design/stl/visual/leg_55.stl" scale="1 1 1"/>
      </geometry>
      <material name="white"/>
    </visual>
  </link>
  <joint name="leg_right_5_revolute_joint" type="revolute">
    <child link="leg_right_5"/>
    <parent link="body_2_part"/>
    <origin rpy="0       0      0" xyz="-0.013 -0.1515  0"/>
    <axis xyz="0 1  0"/>
    <limit effort="30" lower="-1e+100" upper="1e+100" velocity="3.0"/>
    <joint_properties damping="0.0" friction="0.0"/>
  </joint>
  <!-- 		<xacro:property name="angle_coeff_left" value="${(angle_for_0_l_leg + angle_btw_legs * num) % 360 * deg2rad}" />
                <xacro:property name="angle_coeff_right" value="${-(angle_btw_legs * num) % 360 * deg2rad}" /> -->
  <link name="leg_right_4">
    <inertial>
      <mass value="0.010307884"/>
      <origin rpy="0 0 0" xyz="-0.008963344 0 -0.020168668"/>
      <inertia ixx="0.000004032" ixy="0" ixz="0.000000712" iyy="0.000004993" iyz="0" izz="0.000001071"/>
    </inertial>
    <collision>
      <origin rpy="0  0  0" xyz="0 0 0"/>
      <geometry>
        <mesh filename="package://strirus_cad_design/stl/collision/leg_55.stl" scale="1 1 1"/>
      </geometry>
    </collision>
    <visual>
      <origin rpy="0  0  0" xyz="0 0 0"/>
      <geometry>
        <mesh filename="package://strirus_cad_design/stl/visual/leg_55.stl" scale="1 1 1"/>
      </geometry>
      <material name="white"/>
    </visual>
  </link>
  <joint name="leg_right_4_revolute_joint" type="revolute">
    <child link="leg_right_4"/>
    <parent link="body_2_part"/>
    <origin rpy="0       0      0" xyz="0.117 -0.1345  0"/>
    <axis xyz="0 1  0"/>
    <limit effort="30" lower="-1e+100" upper="1e+100" velocity="3.0"/>
    <joint_properties damping="0.0" friction="0.0"/>
  </joint>
  <!-- 		<xacro:property name="angle_coeff_left" value="${(angle_for_0_l_leg + angle_btw_legs * num) % 360 * deg2rad}" />
                <xacro:property name="angle_coeff_right" value="${-(angle_btw_legs * num) % 360 * deg2rad}" /> -->
  <link name="leg_right_3">
    <inertial>
      <mass value="0.010307884"/>
      <origin rpy="0 0 0" xyz="-0.008963344 0 -0.020168668"/>
      <inertia ixx="0.000004032" ixy="0" ixz="0.000000712" iyy="0.000004993" iyz="0" izz="0.000001071"/>
    </inertial>
    <collision>
      <origin rpy="0  0  0" xyz="0 0 0"/>
      <geometry>
        <mesh filename="package://strirus_cad_design/stl/collision/leg_55.stl" scale="1 1 1"/>
      </geometry>
    </collision>
    <visual>
      <origin rpy="0  0  0" xyz="0 0 0"/>
      <geometry>
        <mesh filename="package://strirus_cad_design/stl/visual/leg_55.stl" scale="1 1 1"/>
      </geometry>
      <material name="white"/>
    </visual>
  </link>
  <joint name="leg_right_3_revolute_joint" type="revolute">
    <child link="leg_right_3"/>
    <parent link="body_2_part"/>
    <origin rpy="0       0      0" xyz="0.247 -0.1515  0"/>
    <axis xyz="0 1  0"/>
    <limit effort="30" lower="-1e+100" upper="1e+100" velocity="3.0"/>
    <joint_properties damping="0.0" friction="0.0"/>
  </joint>
  <!-- 		<xacro:property name="angle_coeff_left" value="${(angle_for_0_l_leg + angle_btw_legs * num) % 360 * deg2rad}" />
                <xacro:property name="angle_coeff_right" value="${-(angle_btw_legs * num) % 360 * deg2rad}" /> -->
  <link name="leg_right_2">
    <inertial>
      <mass value="0.010307884"/>
      <origin rpy="0 0 0" xyz="-0.008963344 0 -0.020168668"/>
      <inertia ixx="0.000004032" ixy="0" ixz="0.000000712" iyy="0.000004993" iyz="0" izz="0.000001071"/>
    </inertial>
    <collision>
      <origin rpy="0  0  0" xyz="0 0 0"/>
      <geometry>
        <mesh filename="package://strirus_cad_design/stl/collision/leg_55.stl" scale="1 1 1"/>
      </geometry>
    </collision>
    <visual>
      <origin rpy="0  0  0" xyz="0 0 0"/>
      <geometry>
        <mesh filename="package://strirus_cad_design/stl/visual/leg_55.stl" scale="1 1 1"/>
      </geometry>
      <material name="white"/>
    </visual>
  </link>
  <joint name="leg_right_2_revolute_joint" type="revolute">
    <child link="leg_right_2"/>
    <parent link="body_1_part"/>
    <origin rpy="0       0      0" xyz="0.26 -0.1345  0"/>
    <axis xyz="0 1  0"/>
    <limit effort="30" lower="-1e+100" upper="1e+100" velocity="3.0"/>
    <joint_properties damping="0.0" friction="0.0"/>
  </joint>
  <!-- 		<xacro:property name="angle_coeff_left" value="${(angle_for_0_l_leg + angle_btw_legs * num) % 360 * deg2rad}" />
                <xacro:property name="angle_coeff_right" value="${-(angle_btw_legs * num) % 360 * deg2rad}" /> -->
  <link name="leg_right_1">
    <inertial>
      <mass value="0.010307884"/>
      <origin rpy="0 0 0" xyz="-0.008963344 0 -0.020168668"/>
      <inertia ixx="0.000004032" ixy="0" ixz="0.000000712" iyy="0.000004993" iyz="0" izz="0.000001071"/>
    </inertial>
    <collision>
      <origin rpy="0  0  0" xyz="0 0 0"/>
      <geometry>
        <mesh filename="package://strirus_cad_design/stl/collision/leg_55.stl" scale="1 1 1"/>
      </geometry>
    </collision>
    <visual>
      <origin rpy="0  0  0" xyz="0 0 0"/>
      <geometry>
        <mesh filename="package://strirus_cad_design/stl/visual/leg_55.stl" scale="1 1 1"/>
      </geometry>
      <material name="white"/>
    </visual>
  </link>
  <joint name="leg_right_1_revolute_joint" type="revolute">
    <child link="leg_right_1"/>
    <parent link="body_1_part"/>
    <origin rpy="0       0      0" xyz="0.13 -0.1515  0"/>
    <axis xyz="0 1  0"/>
    <limit effort="30" lower="-1e+100" upper="1e+100" velocity="3.0"/>
    <joint_properties damping="0.0" friction="0.0"/>
  </joint>
  <!-- 		<xacro:property name="angle_coeff_left" value="${(angle_for_0_l_leg + angle_btw_legs * num) % 360 * deg2rad}" />
                <xacro:property name="angle_coeff_right" value="${-(angle_btw_legs * num) % 360 * deg2rad}" /> -->
  <link name="leg_right_0">
    <inertial>
      <mass value="0.010307884"/>
      <origin rpy="0 0 0" xyz="-0.008963344 0 -0.020168668"/>
      <inertia ixx="0.000004032" ixy="0" ixz="0.000000712" iyy="0.000004993" iyz="0" izz="0.000001071"/>
    </inertial>
    <collision>
      <origin rpy="0  0  0" xyz="0 0 0"/>
      <geometry>
        <mesh filename="package://strirus_cad_design/stl/collision/leg_55.stl" scale="1 1 1"/>
      </geometry>
    </collision>
    <visual>
      <origin rpy="0  0  0" xyz="0 0 0"/>
      <geometry>
        <mesh filename="package://strirus_cad_design/stl/visual/leg_55.stl" scale="1 1 1"/>
      </geometry>
      <material name="white"/>
    </visual>
  </link>
  <joint name="leg_right_0_revolute_joint" type="revolute">
    <child link="leg_right_0"/>
    <parent link="body_1_part"/>
    <origin rpy="0       0      0" xyz="0.0 -0.1345  0"/>
    <axis xyz="0 1  0"/>
    <limit effort="30" lower="-1e+100" upper="1e+100" velocity="3.0"/>
    <joint_properties damping="0.0" friction="0.0"/>
  </joint>
</robot>

